Workbook
Name __ALL2: [1]CostPlan!#REF!
Name __MUP3: [1]Rates!$D$116
Name _1: #REF!
Name _10: #REF!
Name _11: #REF!
Name _12: #REF!
Name _13: #REF!
Name _14: #REF!
Name _15: #REF!
Name _16: #REF!
Name _17: #REF!
Name _18: #REF!
Name _19: #REF!
Name _20: #REF!
Name _21: #REF!
Name _22: #REF!
Name _7: #REF!
Name _8: #REF!
Name _9: #REF!
Name _ALL1: #REF!
Name _ALL2: #REF!
Name _ALL3: #REF!
Name _MUP3: [2]Rates!#REF!
Name ajay: '[3]Schedule of Rates'!#REF!
Name ALL: #REF!
Name ar: [4]Rates!$D$48
Name area: [2]Areas!$I$84
Name Areas: [2]Areas!#REF!
Name BASEX: [5]Database!$F$24
Name bat: '[3]Schedule of Rates'!#REF!
Name BULK_EARTHW: Costplan!#REF!
Name CAVFDNS: [6]Database!$F$43
Name CEILINGS: Costplan!$D$196
Name Cfwk: '[3]Schedule of Rates'!$C$25
Name CLEAR: [5]Database!$F$20
Name CTF: [5]Database!$F$22
Name CTS: [5]Database!$F$23
Name currency: '[3]Initial Data'!$G$20
Name DD: Costplan!$D$305
Name dfdf: '[7]Initial Data'!$G$28
Name dfe: '[7]Initial Data'!$G$26
Name dsflkj: [8]Areas!$K$149
Name e.10: '[9]Cost Plan'!#REF!
Name e.11: '[9]Cost Plan'!#REF!
Name e.12: '[3]Cost Plan'!#REF!
Name e.13: '[9]Cost Plan'!#REF!
Name e.14: '[3]Cost Plan'!$A$2331
Name e.15: '[9]Cost Plan'!#REF!
Name e.16: '[9]Cost Plan'!#REF!
Name e.17: '[9]Cost Plan'!#REF!
Name e.18: '[9]Cost Plan'!#REF!
Name e.19: '[3]Cost Plan'!#REF!
Name e.20: '[9]Cost Plan'!#REF!
Name e.21: '[3]Cost Plan'!#REF!
Name e.22: '[9]Cost Plan'!#REF!
Name e.23: '[9]Cost Plan'!#REF!
Name e.24: '[3]Cost Plan'!#REF!
Name e.3: '[9]Cost Plan'!$A$34
Name e.5: '[3]Cost Plan'!$A$47
Name e.6: '[3]Cost Plan'!$A$54

Sheet Summary
B1: 775 Pretoria Chapter - Bible House | L1: 775BH/ Sch 1 Rev 0
B2: Scheme 1 Revision 0 | L2: 45980
B3: Residential
G5: Elemental Quantity | H5: Unit | I5: Rate/m² Element | J5: Total | K5: Rate/m² Building Area | L5: Percentage
I6: R/m² | J6: R | K6: R/m² | L6: %
C8: Executive Summary
B10: 1 | C10: =Costplan!D10 -> Roofs | G10: =Costplan!H31 -> 246 | H10: =Costplan!I31 -> m² | I10: =Costplan!J31 -> 127.70325 | J10: =ROUND(Costplan!M31,-2) -> 31400 | K10: =Costplan!K31 -> 119.9 | L10: =J10/$J$27 -> 0.060864509
B12: 2 | C12: =Costplan!D33 -> External Walling | G12: =Costplan!H57 -> 1700 | H12: =Costplan!I57 -> m² | I12: =Costplan!J57 -> 60 | J12: =ROUND(Costplan!M57,-2) -> 102000 | K12: =Costplan!K57 -> 389.31 | L12: =J12/$J$27 -> 0.19771274
B14: 3 | C14: =Costplan!D59 -> Internal Divisions | G14: =Costplan!H119 -> 296 | H14: =Costplan!I119 -> m² | I14: =Costplan!J119 -> 114.94764 | J14: =ROUND(Costplan!M119,-2) -> 34000 | K14: =Costplan!K119 -> 129.86 | L14: =J14/$J$27 -> 0.065904245
V15: =0.6*(1+V17) -> 0.8
B16: 4 | C16: =Costplan!D121 -> Floor Finishes | G16: =Costplan!H168 -> 420 | H16: =Costplan!I168 -> m² | I16: =Costplan!J168 -> 257.43571 | J16: =ROUND(Costplan!M168,-2) -> 108100 | K16: =Costplan!K168 -> 412.68 | L16: =J16/$J$27 -> 0.20953673
V17: =(0.9-0.6)/0.9 -> 0.33333333
B18: 5 | C18: =Costplan!D170 -> Internal Wall Finishings | G18: =Costplan!H194 -> 468 | H18: =Costplan!I194 -> m² | I18: =Costplan!J194 -> 75 | J18: =ROUND(Costplan!M194,-2) -> 35100 | K18: =Costplan!K194 -> 267.94 | L18: =J18/$J$27 -> 0.068036441
B20: 6 | C20: =Costplan!D196 -> Ceilings | G20: =Costplan!H225 -> 171 | H20: =Costplan!I225 -> m² | I20: =Costplan!J225 -> 102.50292 | J20: =ROUND(Costplan!M225,-2) -> 17500 | K20: =Costplan!K225 -> 56.02 | L20: =J20/$J$27 -> 0.033921303
B22: 7 | C22: =Costplan!D229 -> Plumbing Installation | G22: =Costplan!H301 -> 262 | H22: =Costplan!I301 -> m² | I22: =Costplan!J301 -> 621.19084 | J22: =ROUND(Costplan!M301,-2) -> 162800 | K22: =Costplan!K301 -> 621.19 | L22: =J22/$J$27 -> 0.31556503
B24: 8 | C24: =Costplan!D305 -> Contingency | G24: =Costplan!H310 -> 0 | H24: =Costplan!I310 -> m² | I24: =Costplan!J310 -> 0 | J24: =ROUND(Costplan!M310,-3) -> 25000 | K24: =Costplan!K310 -> 99.85 | L24: =J24/$J$27 -> 0.048459004
C27: =Costplan!D314 -> COST PER m² OF CONSTRUCTION AREA | G27: =Costplan!H314 -> 262 | H27: m² | I27: =J27/G27 -> 1969.084 | J27: =SUM(J8:J26) -> 515900 | K27: =SUM(K10:K26) -> 2096.75 | L27: =SUM(L10:L24) -> 1
J855: 42

Sheet Costplan
C1: 775 Pretoria Chapter - Bible House | M1: 775BH/ Sch 1 Rev 0
C2: Scheme 1 Revision 0 | M2: 45980
C3: Residential | M3: 0
R4: CHECK FOR
H5: Quantity | I5: Unit | J5: Unit Rate | K5: Rate/m² Building Area | L5: Subtotal | M5: Total | O5: PACKAGE | P5: BWP | Q5: SELECTED | R5: SUBTOTALS
J6: R | K6: R/m² | L6: R | M6: R | R6: / TOTALS
D8: BUILDER'S WORK
C10: 1 | D10: Roofs
C12: =C10+0.01 -> 1.01 | D12: Apply waterproofing to slate roof covering | H12: =ROUND(H14,0) -> 246 | I12: m² | J12: 100 | K12: 93.89313 | M12: =ROUND(+H12*J12,-2) -> 24600 | O12: ROOFING | Q12: =M12 -> 24600
H14: =SUM(H16:H18) -> 246
D16: 1.2 | E16: =[2]Areas!I48 -> 137 | F16: 1 | G16: 1 | H16: =D16*E16*F16*G16 -> 164.4 | I16: main
D17: 1.2 | E17: =[2]Areas!I68 -> 68 | F17: 1 | G17: 1 | H17: =D17*E17*F17*G17 -> 81.6 | I17: hall
C19: =C12+0.01 -> 1.02 | D19: Provision for Rain Water goods | H19: =ROUND(H21,0) -> 117 | I19: m | J19: 50 | K19: 22.519084 | M19: =ROUND(+H19*J19,-2) -> 5900 | O19: ROOFING | Q19: =M19 -> 5900
H21: =SUM(H23:H26) -> 117.2
D23: 2 | E23: 3 | F23: 1 | G23: 1 | H23: =D23*E23*F23*G23 -> 6 | I23: downpipes
D24: 1 | E24: 52.29 | F24: 1 | G24: 1 | H24: =D24*E24*F24*G24 -> 52.29 | I24: gutter
D25: 1 | E25: 33.54 | F25: 1 | G25: 1 | H25: =D25*E25*F25*G25 -> 33.54 | I25: gutter
D26: 1 | E26: 25.37 | F26: 1 | G26: 1 | H26: =D26*E26*F26*G26 -> 25.37 | I26: gutter
C28: =C19+0.01 -> 1.03 | D28: Provision for contractors mark-up for profit and attendance on selected subcontractors work | H28: 0.03 | J28: =SUM(Q10:Q29) -> 30500 | K28: 3.4923664 | M28: =ROUND(+H28*J28,0) -> 915 | O28: MARK-UP | P28: =M28 -> 915
D31: =CONCATENATE("Subtotal ",D10) -> Subtotal Roofs | H31: =H12 -> 246 | I31: m² | J31: =M31/H31 -> 127.70325 | K31: 119.9 | M31: =SUM(M10:M30) -> 31415 | N31: =R31 -> 31415 | R31: =SUM(P10:P31)+SUM(Q10:Q31) -> 31415
C33: 2 | D33: External Walling
C35: =C33+0.01 -> 2.01 | D35: One coat plaster to external walls | H35: =ROUND(SUM(H37),0) -> 850 | I35: m² | J35: 80 | K35: 259.54198 | M35: =ROUND(+H35*J35,0) -> 68000 | O35: BWP | P35: =M35 -> 68000
D37: 6.2 | E37: m high | H37: =SUM(H39:H41) -> 849.636
D38: 3 | E38: m high
D40: 2 | E40: =E24 -> 52.29 | F40: =D37 -> 6.2 | G40: 1 | H40: =D40*E40*F40*G40 -> 648.396
D41: 2 | E41: =E25 -> 33.54 | F41: =D38 -> 3 | G41: 1 | H41: =D41*E41*F41*G41 -> 201.24
D42: 1 | E42: =E26 -> 25.37 | F42: =D38 -> 3 | G42: 1 | H42: =D42*E42*F42*G42 -> 76.11
C45: =C35+0.01 -> 2.02 | D45: Prime, undercoat and PVA to walls | H45: =ROUND(SUM(H47),0) -> 850 | I45: m² | J45: 40 | K45: 129.77099 | M45: =ROUND(+H45*J45,0) -> 34000 | O45: BWP | P45: =M45 -> 34000
H47: =SUM(H48:H51) -> 850
D49: 1 | E49: =H35 -> 850 | F49: 1 | G49: 1 | H49: =D49*E49*F49*G49 -> 850
C54: =C45+0.01 -> 2.03 | D54: Provision for contractors mark-up for profit and attendance on selected subcontractors work | H54: 0.03 | J54: =SUM(Q32:Q54) -> 0 | K54: 0 | M54: =ROUND(+H54*J54,0) -> 0 | O54: MARK-UP | P54: =M54 -> 0
D57: =CONCATENATE("Subtotal ",D33) -> Subtotal External Walling | H57: =H35+H45 -> 1700 | I57: m² | J57: =M57/H57 -> 60 | K57: 389.31 | M57: =SUM(M33:M56) -> 102000 | N57: =R57 -> 102000 | R57: =SUM(P32:P57)+SUM(Q32:Q57) -> 102000
C59: 3 | D59: Internal Divisions
C61: =C59+0.01 -> 3.01 | D61: Break 220mm Brick walls to create an opening | H61: =ROUND(H64,0) -> 62 | I61: m² | J61: =M61/H61 -> 223.25806 | K61: 52.832061 | M61: =ROUND(SUM(L61:L93),0) -> 13842
D63: 3 | E63: m high
H64: =SUM(H66:H70) -> 61.599
D66: 1 | E66: 6.02 | F66: =D63 -> 3 | G66: 1 | H66: =D66*E66*F66*G66 -> 18.06
D67: 1 | E67: 6.32 | F67: =D63 -> 3 | G67: 1 | H67: =D67*E67*F67*G67 -> 18.96
D68: 1 | E68: 3.88 | F68: =D63 -> 3 | G68: 1 | H68: =D68*E68*F68*G68 -> 11.64
D69: 1 | E69: 3.62 | F69: =D63 -> 3 | G69: 1 | H69: =D69*E69*F69*G69 -> 10.86
...
